Workbook

Sheet Workplan Chart
A1: PhD MSMF WORKPLAN CHART AND TIMELINE
A2: WORKSTREAM / TASK | B2: STATUS / MILESTONE | C2: YEAR 0 (2026) | F2: YEAR 1 (2027) | R2: YEAR 2 (2028) | AD2: YEAR 3 (2029) | AP2: YEAR 4 (2030)
C3: Oct | D3: Nov | E3: Dec | F3: Jan | G3: Feb | H3: Mar | I3: Apr | J3: May | K3: Jun | L3: Jul | M3: Aug | N3: Sep | O3: Oct | P3: Nov | Q3: Dec | R3: Jan | S3: Feb | T3: Mar | U3: Apr | V3: May | W3: Jun | X3: Jul | Y3: Aug | Z3: Sep | AA3: Oct | AB3: Nov | AC3: Dec | AD3: Jan | AE3: Feb | AF3: Mar | AG3: Apr | AH3: May | AI3: Jun | AJ3: Jul | AK3: Aug | AL3: Sep | AM3: Oct | AN3: Nov | AO3: Dec | AP3: Jan | AQ3: Feb | AR3: Mar | AS3: Apr | AT3: May | AU3: Jun | AV3: Jul | AW3: Aug
A4: PRE-APPLICATION MANUSCRIPT WORK
A5: BCR reconstruction and QC: GSE166780 + GSE173983 | B5: Ongoing
A6: TRUST4 / MiXCR comparison and repertoire analyses beyond bcRflow | B6: Ongoing
A7: Antigen-dependent analysis and candidate prioritisation | B7: Planned
A8: AlphaFold-Multimer pilot and structural interpretation | B8: Planned
A9: Tissue dataset analysis and manuscript consolidation | B9: Planned
A10: APPLICATION AND ADMISSION
A11: PhD application — January | B11: A | F11: A
A12: Admission presentation | B12: AP | F12: AP
A13: PROPOSAL AND REGISTRATION
A14: Form DAC and prepare 10–15 page proposal | B14: Planned
A15: Submit Manuscript 1: public blood/tissue data (Aim 2A) | B15: M1 | H15: M1
A16: MSMF protocol presentation to DAC | B16: P1 | K16: P1
A17: Respond to DAC comments and collect signatures | B17: 7d | K17: 7d
A18: Submit proposal to MAHE; MAHE PPAC / registration | B18: P2 | L18: P2
A19: DAC 1: report of MAHE presentation | B19: D1 | N19: D1
A20: YEAR 1: SEP 2027–AUG 2028
A21: Complete 12 coursework credits | B21: Planned
A22: Obtain ethics approval for Aim 2B before recruitment - PARALLEL to AIM A | B22: E | N22: E
A23: Extend public-data analysis: tissue vs PBMC; stable vs advanced disease | B23: Planned
A24: Design CT calcium score cohort study and confirm clinical partner | B24: Planned
A25: Recruitment and PBMC collection (about 20 patients) | B25: Planned
A26: Draft/submit review article; first conference/poster | B26: R1 | T26: R1
A27: YEAR 3: SEP 2028–AUG 2029
A28: Finish recruitment; RNA extraction, QC, library preparation and RNA-seq | B28: Planned
A29: Optional antigen-dependent / AlphaFold analysis on selected candidates | B29: Planned
A30: DAC 2–5: six-monthly presentations and progress reports | B30: D2–D5 | T30: D2–D5
A31: Second conference/poster presentation | B31: C2 | AF31: C2
A32: BCR reconstruction and repertoire analysis of new RNA-seq | B32: Planned
A33: Explore repertoire associations with CT calcium score | B33: Planned
A34: YEAR 3: SEP 2029–AUG 2030
A35: Submit Manuscript 2 (Aim 2B); thesis writing alongside papers | B35: M2 | AL35: M2
A36: Grant concept note / wider blood-based prognostic study | B36: Planned
A37: DAC 6: seek permission for open synopsis presentation | B37: D6 | AR37: D6
A38: Open synopsis presentation | B38: S | AR38: S
A39: Turnitin report (<15%) and CDS NOC | B39: NOC | AV39: NOC
A40: Thesis submission to Registrar (Evaluation) | B40: T | AW40: T
...

Sheet Task Tracker
A1: ID | B1: Month | C1: Workstream | D1: Task / Goal | E1: Estimated effort (days) | F1: Status | G1: Definition of done / deliverable | H1: Next action / notes | I1: Deadline type | J1: Latest date / rule
A2: 1 | B2: October | C2: Planning | D2: Audit existing analysis and freeze blood-dataset sample metadata | E2: 2 | F2: Not Started | G2: Verified sample sheet, group labels, inclusion/exclusion rules | H2: Confirm counts and conditions for GSE166780 and GSE173983 | I2: Planned
A3: 2 | B3: October | C3: BCR reconstruction | D3: Re-run reconstruction on GSE166780 | E3: 5 | F3: Not Started | G3: Per-sample outputs, logs, tool versions, parameters and QC recorded | H3: Compare rerun with existing TRUST4 and MiXCR outputs | I3: Planned
A4: 3 | B4: October | C4: BCR reconstruction | D4: Re-run reconstruction on GSE173983 | E4: 3 | F4: Not Started | G4: Per-sample outputs, logs and QC recorded | H4: Keep validation cohort separate | I4: Planned
A5: 4 | B5: October | C5: Pipeline comparison | D5: Compare TRUST4 and MiXCR reconstruction outputs | E5: 4 | F5: Not Started | G5: Per-sample summary of productive contigs, chain recovery, QC and failures | H5: Do not select a tool on total sequence counts alone | I5: Planned
A6: 5 | B6: October | C6: Repertoire analysis | D6: Run diversity/repertoire tools beyond bcRflow | E6: 6 | F6: Not Started | G6: Reproducible sample-level metrics and figures for both cohorts | H6: Assess diversity, clonality, V/J usage, CDR3 and isotype where supported | I6: Planned
A7: 6 | B7: October | C7: Statistics | D7: Create cross-dataset analysis table and statistical plan | E7: 3 | F7: Not Started | G7: Master table, planned group comparisons and documented cohort limitations | H7: GSE173983 is very small (n=4 total per documentation) | I7: Planned
A8: 7 | B8: October | C8: Manuscript | D8: Create manuscript skeleton and figure plan | E8: 2 | F8: Not Started | G8: Working title, aims, Methods outline and planned figures | H8: Keep claims proportionate to the public bulk RNA-seq cohorts | I8: Planned
A9: 8 | B9: November | C9: Antigen-dependent analysis | D9: Audit and consolidate existing antigen-dependent outputs | E9: 3 | F9: Not Started | G9: Inventory of candidates, antigen list, pairing/structure status and gaps | H9: Mark what is complete, needs rerunning, or is not reliable | I9: Planned
A10: 9 | B10: November | C10: Antigen-dependent analysis | D10: Prioritise candidate BCR/antibody sequences | E10: 4 | F10: Not Started | G10: Transparent candidate-selection criteria and ranked candidate list | H10: Clonal expansion is not by itself proof of antigen specificity | I10: Planned
A11: 10 | B11: November | C11: Antigen-dependent analysis | D11: Complete or refresh antigen-dependent analysis for selected candidates | E11: 8 | F11: Not Started | G11: Reproducible candidate–antigen table and interpretable figures | H11: Record antigen structure/provenance and uncertainty | I11: Planned
A12: 11 | B12: November | C12: Structural modelling | D12: Decide where AlphaFold/AlphaFold-Multimer may help | E12: 3 | F12: Not Started | G12: Short methods decision note and pilot design | H12: Check chain setup, antigen construct and complex confidence metrics | I12: Planned
A13: 12 | B13: November | C13: Structural modelling | D13: Run a small AlphaFold complex-modelling pilot | E13: 5 | F13: Not Started | G13: Pilot structures and quality summary compared with existing docking | H13: Predicted structures/confidence are not proof of binding | I13: Planned
... A24: 23 | B24: January 2027 | C24: Manuscript | D24: Supervisor review and revision of the pre-admission manuscript draft | E24: 5 | F24: Not Started | G24: Reviewed draft with an agreed list of revisions and open claims | H24: Keep claims proportionate to the public bulk RNA-seq data | I24: Planned
A25: 24 | B25: January 2027 | C25: Application | D25: Confirm eligibility and PI funding/interest, then email the application to the PhD office | E25: 2 | F25: Not Started | G25: Application sent in the January intake; test-waiver status known | H25: Written test is waived for staff with more than 6 months at MSMF - confirm if this applies. Send to phd.office@ms-mf.org | I25: FIXED | J25: January 2027 intake
A26: 25 | B26: January 2027 | C26: Application | D26: Prepare the admission presentation: rationale and at least two aims (Aim 2A, Aim 2B) | E26: 6 | F26: Not Started | G26: Short deck with rationale, both aims, preliminary results from the Oct-Dec work and expected outcomes | H26: Aim 1 (agent-based model) is on hold per the supervisor; leave it out unless he asks | I26: Planned
A27: 26 | B27: Jan-Feb 2027 | C27: Application | D27: Written test, if not waived | E27: 4 | F27: Not Started | G27: Test completed | H27: Covers basic statistics, chemistry, instrumentation, cell and molecular biology. Skip if waived | I27: Planned
A28: 27 | B28: February 2027 (assumed) | C28: Admission | D28: Admission presentation to MSMF - Day 0 for all coordinator ceilings | E28: 1 | F28: Not Started | G28: Presentation delivered and selection outcome received | H28: Assumed date. Update the yellow date on Key Deadlines once MSMF confirms | I28: FIXED | J28: ='Key Deadlines'!E8 -> 46444
A29: 28 | B29: Feb-Mar 2027 | C29: Admission | D29: Complete MAHE admission: admission order form, joining report, fee payment | E29: 3 | F29: Not Started | G29: Admission order and joining report filed; fees paid | H29: Late fee payment can cancel registration | I29: Planned
A30: 29 | B30: Mar-Apr 2027 | C30: Proposal | D30: Form the DAC (maximum 8 members, including an external clinician and a clinician from the sample source) | E30: 3 | F30: Not Started | G30: DAC list agreed by the PhD coordinator and supervisor | H30: Aim 2B needs a clinician from the sample-collection site (NH or another partner) | I30: FIXED | J30: ='Key Deadlines'!E9 -> 46625
A31: 30 | B31: Mar-May 2027 | C31: Proposal | D31: Write the 10-15 page proposal: two aims, Gantt chart, preliminary work, clinical relevance, translational outcome/IP | E31: 15 | F31: Not Started | G31: Supervisor-approved proposal in MAHE format, with Turnitin report | H31: Needs an external funding plan and a supervisor declaration | I31: Planned
A32: 31 | B32: Mar-Aug 2027 | C32: Manuscript | D32: Submit manuscript 1 (Aim 2A, public blood and tissue data) to a journal with IF 3.0 or higher | E32: 10 | F32: Not Started | G32: Manuscript submitted; first author, guide corresponding | H32: MAHE affiliation is needed for it to count as a required paper; check with the coordinator since the work started before admission | I32: Planned
A33: 32 | B33: Jun 2027 (planned) | C33: Proposal | D33: Protocol presentation at MSMF to the DAC (1-page summary to members at least 3 days before) | E33: 3 | F33: Not Started | G33: Presentation delivered; DAC comments recorded | H33: Coordinator ceiling is 6 months after the admission presentation | I33: FIXED | J33: ='Key Deadlines'!E9 -> 46625
A34: 33 | B34: Within 7 days | C34: Proposal | D34: Respond to DAC comments and collect signatures | E34: 2 | F34: Not Started | G34: Signed response circulated to all DAC members | H34: Applies after every DAC presentation, not just this one | I34: FIXED | J34: 7 days after each DAC
A35: 34 | B35: Aug 2027 (planned) | C35: Registration | D35: Submit proposal and Turnitin report to MAHE, then present to the MAHE PPAC (4-6 weeks after submission) | E35: 4 | F35: Not Started | G35: PPAC approval; the presentation date becomes the registration date | H35: Submit soon after the MSMF presentation so the PPAC lands inside the 2-month ceiling | I35: FIXED | J35: ='Key Deadlines'!E10 -> 46686
A36: 35 | B36: Sep 2027 (planned) | C36: Registration | D36: DAC 1: report on the MAHE presentation | E36: 1 | F36: Not Started | G36: DAC 1 minutes filed; next DAC date set | H36: Board ceiling is 2 weeks after the PPAC | I36: FIXED | J36: ='Key Deadlines'!E11 -> 46700
A37: 36 | B37: Y1 H1 (Sep 2027-Feb 2028) | C37: Coursework | D37: Complete 12 credits: 6 research-specific, 4 methodology, 2 publication ethics | E37: 24 | F37: Not Started | G37: Transcript and comprehensive grade sheet | H37: One credit is 16 learning hours. Missing the deadline cancels registration | I37: FIXED | J37: ='Key Deadlines'!E21 -> 46809
A38: 37 | B38: Y1 H1 (Sep 2027-Feb 2028) | C38: Ethics | D38: Ethics approval for Aim 2B patient samples and data (IBSC only if recombinant DNA is involved) | E38: 10 | F38: Not Started | G38: Approvals in hand before any recruitment | H38: Guidelines say 6 months in one place and 1 year in another; plan to 6 months | I38: FIXED | J38: ='Key Deadlines'!E22 -> 46809
A39: 38 | B39: Y1 H1 (Sep 2027-Feb 2028) | C39: Aim 2A | D39: Extend public-data analysis: tissue vs PBMC, and stable vs advanced disease, for antigen-independent and antigen-specific features | E39: 40 | F39: Not Started | G39: Comparative results with caveats; patterns that separate stable from advanced | H39: Reuse the Oct-Dec pipeline; compare only compatible study designs | I39: Planned
A40: 39 | B40: Y1 H1 (Sep 2027-Feb 2028) | C40: Aim 2B | D40: Design the CT calcium score study: clinical partner, mild (1-99) vs advanced (299 or more) criteria, n about 20, consent, sequencing plan | E40: 20 | F40: Not Started | G40: Study protocol, partner agreement and sample-handling SOPs | H40: Settle NH or another partner early; everything in Aim 2B depends on it | I40: Planned
A41: 40 | B41: Y1 H1 (Sep 2027-Feb 2028) | C41: Manuscript | D41: Respond to reviewer comments on manuscript 1 and resubmit if needed | E41: 10 | F41: Not Started | G41: Revised manuscript and response letter | H41: Timing depends on the journal | I41: Planned
A42: 41 | B42: Y1 H2 to Y2 H2 (Mar 2028-Aug 2029) | C42: DAC cycle | D42: DAC 2-5: six-monthly DAC presentation, response within 7 days, and progress report to MAHE after each | E42: 12 | F42: Not Started | G42: Four DAC meetings with minutes, each followed by a MAHE progress report | H42: Two consecutive missed reports cancels registration. Reports are 10-12 pages with DAC recommendation and coursework status | I42: FIXED | J42: ='Key Deadlines'!E15 -> 47431
A43: 42 | B43: Y1 H2 (Mar-Aug 2028) | C43: Aim 2B | D43: Start recruitment and PBMC collection (about 20 patients, mild vs advanced) | E43: 60 | F43: Not Started | G43: Banked PBMC samples with clinical metadata and calcium scores | H43: Recruitment pace is the main schedule risk; start only after ethics approval | I43: Planned
A44: 43 | B44: Y1 H2 (Mar-Aug 2028) | C44: Publications | D44: Draft a review article on BCR repertoires in atherosclerosis | E44: 25 | F44: Not Started | G44: Review submitted | H44: Can count as one of the two required papers, which protects the schedule if Aim 2B runs late | I44: Planned
A45: 44 | B45: Y1 H2 (Mar-Aug 2028) | C45: Conferences | D45: First conference or poster presentation | E45: 5 | F45: Not Started | G45: Presentation certificate | H45: Two are needed before thesis submission | I45: Planned
A46: 45 | B46: Y2 H1 (Sep 2028-Feb 2029) | C46: Aim 2B | D46: Finish recruitment; RNA extraction, QC and library preparation | E46: 40 | F46: Not Started | G46: All samples collected; RNA QC records | H46: Agree in-house vs vendor sequencing early | I46: Planned
A47: 46 | B47: Y2 H1 (Sep 2028-Feb 2029) | C47: Aim 2B | D47: RNA-seq of the PBMC samples | E47: 20 | F47: Not Started | G47: Raw reads with QC | H47: Funding for sequencing comes from the external grant plan | I47: Planned
A48: 47 | B48: Y2 H1 (Sep 2028-Feb 2029) | C48: Antigen-dependent analysis | D48: Optional: antigen-dependent and AlphaFold analysis on selected candidates from Aim 2A | E48: 30 | F48: Not Started | G48: Candidate-antigen table and figures with limitations | H48: Cut first if time is short | I48: Planned
A49: 48 | B49: Y2 H2 (Mar-Aug 2029) | C49: Aim 2B | D49: BCR reconstruction and repertoire analysis of the new RNA-seq, using the validated pipeline | E49: 40 | F49: Not Started | G49: Per-patient repertoire metrics and QC | H49: Reuse the tool decisions from the Oct-Dec comparison | I49: Planned
A50: 49 | B50: Y2 H2 (Mar-Aug 2029) | C50: Aim 2B | D50: Association of repertoire properties (diversity, clonality, isotype, V/J, CDR3) with CT calcium score | E50: 30 | F50: Not Started | G50: Exploratory associations with effect sizes and caveats | H50: About 20 patients supports exploratory findings, not definitive claims | I50: Planned
...

Sheet Key Deadlines
A1: Fixed deadlines and milestone dates
A3: Admission presentation date (ASSUMED - edit when MSMF confirms) | B3: 46444 | C3: Everything below recalculates from these dates. Only the yellow cells are inputs.
A4: MSMF protocol presentation - planned (overwrite with the real date) | B4: =EDATE(B3,4) -> 46564
A5: MAHE PPAC presentation = registration date - planned (overwrite with the real date) | B5: =EDATE(B3,6) -> 46625
A7: Milestone | B7: Source | C7: Rule | D7: Planned date | E7: Latest date | F7: Notes
A8: Admission presentation (Day 0) | B8: Coordinator board | C8: Start of every ceiling below | D8: =B3 -> 46444 | E8: =B3 -> 46444 | F8: Assumed date; the PhD office sets the real one.
A9: Protocol presentation at MSMF; DAC formed | B9: Coordinator board | C9: At most 6 months after the admission presentation | D9: =B4 -> 46564 | E9: =EDATE(B3,6) -> 46625 | F9: Circulate a 1-page summary to the DAC at least 3 days before. Respond to comments within 7 days.
A10: Protocol presentation at MAHE (PPAC) = registration date | B10: Coordinator board; guidelines 8.3.3 | C10: At most 2 months after the MSMF presentation | D10: =B5 -> 46625 | E10: =EDATE(E9,2) -> 46686 | F10: MAHE schedules the PPAC 4-6 weeks after you submit, so submit soon after the MSMF presentation.
A11: DAC 1 - report of the MAHE presentation | B11: Coordinator board | C11: At most 2 weeks after the PPAC | D11: =D10+14 -> 46639 | E11: =E10+14 -> 46700
A12: DAC 2 | B12: Coordinator board; guidelines 9.2 | C12: Every 6 months from DAC 1 | D12: =EDATE($D$11,6) -> 46821 | E12: =EDATE($E$11,6) -> 46882 | F12: Each DAC is followed by a progress report to MAHE (CDS).
A13: DAC 3 | B13: Coordinator board; guidelines 9.2 | C13: Every 6 months | D13: =EDATE($D$11,12) -> 47005 | E13: =EDATE($E$11,12) -> 47066
A14: DAC 4 | B14: Coordinator board; guidelines 9.2 | C14: Every 6 months | D14: =EDATE($D$11,18) -> 47186 | E14: =EDATE($E$11,18) -> 47247
A15: DAC 5 | B15: Coordinator board; guidelines 9.2 | C15: DAC 2-5 within 2 years of DAC 1 | D15: =EDATE($D$11,24) -> 47370 | E15: =EDATE($E$11,24) -> 47431 | F15: The board shows 2 years against "DAC 2-5".
A16: DAC 6 - permission for the open synopsis presentation | B16: Coordinator board; guidelines 10.1 | C16: Sixth DAC meeting; at least 6 progress reports | D16: =EDATE($D$11,30) -> 47551 | E16: =EDATE($E$11,30) -> 47612 | F16: TO CONFIRM: assumes DAC 6 comes 6 months after DAC 5. If the board's 2 years runs DAC 1 to DAC 6, the latest date is 6 months earlier.
A17: Open synopsis presentation (all DAC members present) | B17: Coordinator board | C17: At most 6 months after DAC 6 | D17: =EDATE(D16,5) -> 47704 | E17: =EDATE(E16,6) -> 47796 | F17: Publications must be accepted or published first.
A18: Thesis submission | B18: Coordinator board; guidelines 3 | C18: At most 7 days after the synopsis, and not before the minimum duration | D18: =MAX(D19,D17+7) -> 47721 | E18: =E17+7 -> 47803 | F18: A 2-month grace period applies after the due date only if no extension was taken.
A19: Earliest thesis submission (minimum duration) | B19: MSMF/MAHE guidelines section 3 | C19: At least 3 years from registration AND 3.5 years from admission | D19: =MAX(EDATE(D10,36),EDATE(B3,42)) -> 47721 | E19: =MAX(EDATE(D10,36),EDATE(B3,42)) -> 47721 | F19: Full-time candidates. Extensions need DAC recommendation and university approval.
A20: Maximum duration | B20: MSMF/MAHE guidelines section 3 | C20: At most 6 years from registration (full-time) | E20: =EDATE(D10,72) -> 48817 | F20: Registration is cancelled if the thesis is not submitted by then.
A21: Coursework: 12 credits | B21: MSMF/MAHE guidelines 9.1.1, 9.4 | C21: Within 6 months of registration | D21: =EDATE(D10,5) -> 46778 | E21: =EDATE(D10,6) -> 46809 | F21: 6 research-specific, 4 methodology, 2 publication ethics. Missing it cancels registration. (Section 9.1 elsewhere says before registration - confirm.)
A22: Ethics approval for patient samples/data (Aim 2B) | B22: MSMF/MAHE guidelines 8.1.3 and 5 | C22: Within 6 months of registration (section 5 says 1 year) | D22: =EDATE(D10,5) -> 46778 | E22: =EDATE(D10,6) -> 46809 | F22: Plan to the stricter 6 months. IBSC approval only if recombinant DNA is involved.
A23: Response to DAC comments | B23: MSMF/MAHE guidelines 8.3.1, 9.2 | C23: Within 7 days of each DAC presentation | F23: Signatures: guide, co-guide, coordinator, experts, chairman.
A24: Progress report to MAHE (CDS) | B24: MSMF/MAHE guidelines 9.2, 9.4 | C24: Every 6 months; two consecutive misses cancel registration | F24: Maximum 10-12 pages, with DAC recommendation and coursework status.
A25: Two first-author publications (IF 3.0 or higher) | B25: MSMF/MAHE guidelines 9.3.1 | C25: Published or accepted before the synopsis; MAHE affiliation; guide corresponding author | D25: =D16 -> 47551 | E25: =E17 -> 47796 | F25: One may be a review article.
A26: Two conference or poster presentations | B26: MSMF/MAHE guidelines 9.3.2 | C26: Before thesis submission (DAC may waive with patents and more than two papers) | D26: =D17 -> 47704 | E26: =E18 -> 47803 | F26: Keep the certificates.
A27: Turnitin report (similarity under 15%) and CDS NOC | B27: MSMF/MAHE guidelines 10 | C27: Before submission to the Registrar (Evaluation) | D27: =D17 -> 47704 | E27: =E18 -> 47803 | F27: NOC follows dues clearance.
A28: Check: does the board chain reach the minimum duration? | E28: =IF(E18>=D19,"OK","CHECK") -> OK | F28: OK means the board's ceilings run at least as late as the earliest allowed thesis date, so the two sets of rules do not contradict each other.
A30: Red = fixed deadline (latest date). Amber = fixed but needs confirming. Planned dates are suggestions that leave room before the ceilings.

Sheet Monthly Overview
A1: PhD Roadmap: October 2026 to 2030 (months after December are broad and assume the dates on Key Deadlines)
A3: Month | B3: Primary objective | C3: Key deliverables | D3: Success criterion | E3: Scope guardrail
A4: October 2026 | B4: Redo BCR reconstruction and establish robust blood repertoire results | C4: Reproducible reconstruction; QC and TRUST4/MiXCR comparison; diversity/clonality/VJ/CDR3/isotype analyses beyond bcRflow; figure plan | D4: Sample-level results and defensible repertoire metrics across both blood cohorts | E4: Prioritise reliable comparable methods over adding many tools
A5: November 2026 | B5: Complete antigen-dependent work and assess structural modelling | C5: Consolidated candidate–antigen results; small AlphaFold-Multimer pilot; initial Methods/Results draft | D5: Traceable evidence from candidate selection to structural predictions, with limitations | E5: Predicted structures are hypotheses, not experimental proof of binding
A6: December 2026 | B6: Extend workflow to tissue datasets and consolidate manuscript | C6: Selected tissue dataset(s); QC/reconstruction/repertoire analysis; valid blood–tissue comparisons; revised draft | D6: Coherent manuscript draft ready for supervisor review | E6: If earlier work slips, reduce tissue scope rather than leaving all analyses incomplete
A7: Jan-Feb 2027 | B7: Apply and be admitted | C7: Application sent; admission presentation (assumed late February); MAHE admission paperwork | D7: Selected for the PhD and admitted to MAHE | E7: Do not wait for a perfect manuscript; the January intake is the deadline
A8: Mar-Aug 2027 | B8: Proposal, DAC, protocol presentations, registration | C8: DAC formed; 10-15 page proposal; MSMF presentation (ceiling 6 months after admission presentation); MAHE PPAC (ceiling 2 months later); manuscript 1 submitted | D8: Registered with MAHE and DAC 1 held inside the coordinator ceilings | E8: Submit to MAHE early; the PPAC date is out of your hands
A9: Sep 2027-Aug 2028 (Year 1) | B9: Coursework, ethics, finish Aim 2A, set up Aim 2B | C9: 12 credits and ethics approval inside 6 months of registration; extended public-data analysis; Aim 2B protocol and partner; start recruitment; review article; DAC 2 and DAC 3 start | D9: Coursework and ethics done; recruitment under way | E9: Ethics approval comes before any recruitment
A10: Sep 2028-Aug 2029 (Year 2) | B10: Generate and analyse the Aim 2B data | C10: Recruitment finished; RNA-seq; BCR reconstruction; repertoire-calcium score association; second conference; DAC 3-5 and progress reports | D10: Repertoire results for about 20 patients with caveats | E10: If recruitment is slow, cut the optional antigen-dependent work first
A11: Sep 2029-Feb 2030 (Year 3, first half) | B11: Papers and thesis | C11: Manuscript 2 submitted; thesis chapters; grant groundwork; DAC 5 | D11: Two first-author papers submitted or accepted (one may be a review) | E11: Publications must be accepted before the synopsis
A12: Mar-Aug 2030 | B12: DAC 6, synopsis and thesis submission | C12: DAC 6 permission; open synopsis presentation; Turnitin and NOC; thesis submitted (not before the minimum duration) | D12: Thesis submitted; evaluation and viva follow | E12: Aim 1 is parked and not part of this plan

Sheet Weekly Check-in
A1: Week starting | B1: This week's 1–3 outcomes | C1: Tasks worked on | D1: Completed / evidence | E1: Blockers / decisions | F1: Next week's focus | G1: Supervisor discussion

Sheet Read Me
A1: Purpose | B1: Flexible tracker from October 2026 to thesis submission. October-December 2026 is manuscript work before PhD admission; the application starts in January 2027; later phases are broad.
A2: October | B2: Re-run reconstruction for GSE166780 and GSE173983; compare TRUST4 and MiXCR where useful; run repertoire analyses beyond bcRflow; document QC and statistical design.
A3: November | B3: Consolidate antigen-dependent analysis, prioritise candidates, run a small AlphaFold/AlphaFold-Multimer pilot if appropriate, and draft Methods/Results.
A4: December | B4: Select and analyse a manageable tissue RNA-seq dataset; run reconstruction and repertoire analysis; compare tissue and blood only where study designs support it; consolidate manuscript.
A5: Documentation context | B5: The supplied document describes GSE166780 as 24 samples across noCAD/Mild-CAD/CAD-MI and GSE173983 as 4 samples across healthy/chronic CAD. TRUST4 is the primary route; MiXCR + immunarch is a parallel route. Existing metrics include diversity, clonality, isotype, V/J usage and CDR3.
A6: Planning rule | B6: Target months and effort estimates are flexible planning aids. Only rows marked FIXED carry deadlines, and those come from the coordinator board and the MSMF/MAHE guidelines.
A7: Definition of done | B7: Each task should end with an artifact: QC report, reproducible table, figure, decision note, script or manuscript section.
A8: Manuscript standard | B8: Prioritise a coherent and defensible story over maximum analysis count. Agree minimum scope and claims with your supervisor.
A9: AlphaFold caveat | B9: Predicted structures and confidence metrics do not establish experimental antigen binding; document inputs, candidate selection and uncertainty.
A10: Scope guardrail | B10: If October blood analysis slips, reduce tissue dataset/candidate count rather than spreading effort across too many unfinished analyses.
A11: Colour key | B11: Red cells in "Deadline type" and "Latest date / rule" mark FIXED deadlines, and their task text is bold dark red. Row colours show the phase: green January-February 2027, purple March-August 2027, orange year 1, blue year 2, pink year 3.
A12: Fixed deadlines | B12: The ceilings are the coordinator's: admission presentation to MSMF protocol presentation 6 months; to MAHE 2 months; to DAC 1 2 weeks; DAC 2-5 within 2 years; DAC 6 to synopsis 6 months; synopsis to thesis 7 days. Other fixed items come from the guidelines. All dates are on the Key Deadlines sheet.
... A18: Workplan Chart | B18: First worksheet: Gantt-style month-by-month diagram based on the attached PDF. Red = fixed milestones; green = pre-application/manuscript work; purple = proposal/completion; orange = Year 1; blue = Year 2; teal = ongoing requirements; grey = parked Aim 1.
